<?xml version="1.0"?>

<robot xmlns:xacro="http://ros.org/wiki/xacro" name="husky_wheel">

	<xacro:macro name="omni_wheel" params="wheel_prefix *joint_pose">
		<link name="${wheel_prefix}_wheel_link">
			<inertial>
				<mass value="0.2" />
				<origin xyz="0 0 0" />
				<inertia  ixx="0.00467" ixy="0" ixz="0" iyy="0.00411" iyz="0" izz="0.00467" />
			</inertial>
			<visual>
				<origin xyz="0 0 0" rpy="0 0 0" />
				<geometry>
					<cylinder length="0.03" radius="0.06" />
				</geometry>
			</visual>
			<collision>
				<origin xyz="0 0 0" rpy="0 0 0" />
				<geometry>
					<cylinder length="0.03" radius="0.06" />
				</geometry>
				<surface>
					<bounce restitution_coefficient="0.0001" />
				</surface>
			</collision>
		</link>

		<gazebo reference="${wheel_prefix}_wheel_link">
			<mu1 value="0.2"/>
			<mu2 value="1.5"/>
			<kp value="10000000.0" />
			<kd value="10000.0" />
			<fdir1 value="0 0 1"/>
			<maxContacts value= "1"/>
		</gazebo>

		<joint name="${wheel_prefix}_wheel" type="continuous">
			<parent link="base_link"/>
			<child link="${wheel_prefix}_wheel_link"/>
			<xacro:insert_block name="joint_pose"/>
			<axis xyz="0 0 1" rpy="0 0 0" />
		</joint>

		<transmission name="${wheel_prefix}_wheel_trans" type="SimpleTransmission">
			<type>transmission_interface/SimpleTransmission</type>
			<actuator name="${wheel_prefix}_wheel_motor">
				<mechanicalReduction>1</mechanicalReduction>
			</actuator>
			<joint name="${wheel_prefix}_wheel">
				<hardwareInterface>hardware_interface/VelocityJointInterface</hardwareInterface>
			</joint>
		</transmission>

	</xacro:macro>
</robot>